<?xml version="1.0"?>
<robot xmlns:xacro="http://www.ros.org/wiki/xacro" name="tomato_arm">
    <material name="color1">
        <color rgba="1.0 0.0 0.0 1.0"/> 
    </material>

    <material name="color2">
        <color rgba="0.0 0.8 0.0 1.0"/>
    </material>

    <material name="color3">
        <color rgba="0.0 0.35 1.0 1.0"/>
    </material>

    <material name="color4">
        <color rgba="1.0 0.85 0.0 1.0"/>
    </material>

    <material name="color5">
        <color rgba="0.65 0.20 0.85 1.0"/>
    </material>

    <link name="base_link">
        <visual>
            <origin xyz="0 0 0" rpy="0 0 0"/>
            <geometry>
            <mesh filename="package://tomato_description/meshes/base_link.stl"/>
            </geometry>
            <material name="color1"/>
        </visual>
    </link>

    <joint name="joint_1" type="continuous">
        <parent link="base_link"/>
        <child link="shoulder_link"/>
        <origin xyz="0 0 0" rpy="0 0 0"/>
        <axis xyz="0 0 1"/>
        <limit effort="1.0" velocity="2.0"/>
    </joint>

    <link name="shoulder_link">
        <visual>
            <origin xyz="0 0 0" rpy="0 0 0"/>
            <geometry>
                <mesh filename="package://tomato_description/meshes/shoulder_link.stl"/>
            </geometry>
            <material name="color2"/>
        </visual>
    </link>

    <joint name="joint_2" type="revolute">
        <parent link="shoulder_link"/>
        <child link="forearm_link"/>
        <origin xyz="0 0 0.10597" rpy="0 -1.5708 0"/>
        <axis xyz="0 1 0"/>
        <limit lower="-1.618" upper="1.595" effort="1.0" velocity="2.0"/>
    </joint>

    <link name="forearm_link">
        <visual>
            <origin xyz="0 0 -0.10597" rpy="0 0 0"/>
            <geometry>
                <mesh filename="package://tomato_description/meshes/forearm_link.stl"/>
            </geometry>
            <material name="color3"/>
        </visual>
    </link>

    <joint name="joint_3" type="revolute">
        <parent link="forearm_link"/>
        <child link="elbow_link"/>
        <origin xyz="0.1778 0 0" rpy="0 0 0"/>
        <axis xyz="0 1 0"/>
        <limit lower="-1.825" upper="1.792" effort="1.0" velocity="2.0"/>
    </joint>

    <link name="elbow_link">
        <visual>
            <origin xyz="-0.1778 0 -0.10597" rpy="0 0 0"/>
            <geometry>
                <mesh filename="package://tomato_description/meshes/elbow_link.stl"/>
            </geometry>
            <material name="color4"/>
        </visual>
    </link>

    <joint name="joint_4" type="revolute">
        <parent link="elbow_link"/>
        <child link="wrist_link"/>
        <origin xyz="0.1524 0 0" rpy="0 0 0"/>
        <axis xyz="0 1 0"/>
        <limit lower="-1.855" upper="1.786" effort="1.0" velocity="2.0"/>
    </joint>

    <link name="wrist_link">
        <visual>
            <origin xyz="-0.3302 0 -0.10597" rpy="0 0 0"/>
            <geometry>
                <mesh filename="package://tomato_description/meshes/wrist_link.stl"/>
            </geometry>
            <material name="color5"/>
        </visual>
    </link>

</robot>